2024-10-08 12:54:53,183 INFO    MainThread:86111 [wandb_setup.py:_flush():79] Current SDK version is 0.18.3
2024-10-08 12:54:53,183 INFO    MainThread:86111 [wandb_setup.py:_flush():79] Configure stats pid to 86111
2024-10-08 12:54:53,183 INFO    MainThread:86111 [wandb_setup.py:_flush():79] Loading settings from /Users/mbardiot/.config/wandb/settings
2024-10-08 12:54:53,183 INFO    MainThread:86111 [wandb_setup.py:_flush():79] Loading settings from /Users/mbardiot/Library/CloudStorage/GoogleDrive-mbardiot@deezer.com/My Drive/ecole/meditime/MEDITIME/wandb/settings
2024-10-08 12:54:53,183 INFO    MainThread:86111 [wandb_setup.py:_flush():79] Loading settings from environment variables: {}
2024-10-08 12:54:53,183 INFO    MainThread:86111 [wandb_setup.py:_flush():79] Applying setup settings: {'mode': None, '_disable_service': None}
2024-10-08 12:54:53,183 INFO    MainThread:86111 [wandb_setup.py:_flush():79] Inferring run settings from compute environment: {'program_relpath': 'main.py', 'program_abspath': '/Users/mbardiot/Library/CloudStorage/GoogleDrive-mbardiot@deezer.com/My Drive/ecole/meditime/MEDITIME/main.py', 'program': '/Users/mbardiot/Library/CloudStorage/GoogleDrive-mbardiot@deezer.com/My Drive/ecole/meditime/MEDITIME/main.py'}
2024-10-08 12:54:53,183 INFO    MainThread:86111 [wandb_setup.py:_flush():79] Applying login settings: {}
2024-10-08 12:54:53,183 INFO    MainThread:86111 [wandb_init.py:_log_setup():532] Logging user logs to /Users/mbardiot/Library/CloudStorage/GoogleDrive-mbardiot@deezer.com/My Drive/ecole/meditime/MEDITIME/wandb/run-20241008_125453-yc7xl5tr/logs/debug.log
2024-10-08 12:54:53,183 INFO    MainThread:86111 [wandb_init.py:_log_setup():533] Logging internal logs to /Users/mbardiot/Library/CloudStorage/GoogleDrive-mbardiot@deezer.com/My Drive/ecole/meditime/MEDITIME/wandb/run-20241008_125453-yc7xl5tr/logs/debug-internal.log
2024-10-08 12:54:53,183 INFO    MainThread:86111 [wandb_init.py:init():617] calling init triggers
2024-10-08 12:54:53,183 INFO    MainThread:86111 [wandb_init.py:init():624] wandb.init called with sweep_config: {}
config: {'learning_rate': 0.02, 'architecture': 'CNN', 'dataset': 'CIFAR-100', 'epochs': 10}
2024-10-08 12:54:53,183 INFO    MainThread:86111 [wandb_init.py:init():667] starting backend
2024-10-08 12:54:53,183 INFO    MainThread:86111 [wandb_init.py:init():671] sending inform_init request
2024-10-08 12:54:53,184 INFO    MainThread:86111 [backend.py:_multiprocessing_setup():104] multiprocessing start_methods=spawn,fork,forkserver, using: spawn
2024-10-08 12:54:53,184 INFO    MainThread:86111 [wandb_init.py:init():684] backend started and connected
2024-10-08 12:54:53,186 INFO    MainThread:86111 [wandb_init.py:init():779] updated telemetry
2024-10-08 12:54:53,199 INFO    MainThread:86111 [wandb_init.py:init():812] communicating run to backend with 90.0 second timeout
2024-10-08 12:55:56,482 INFO    Thread-1 (wrapped_target):86111 [retry.py:__call__():172] Retry attempt failed:
Traceback (most recent call last):
  File "/Library/Frameworks/Python.framework/Versions/3.12/lib/python3.12/site-packages/urllib3/connection.py", line 174, in _new_conn
    conn = connection.create_connection(
           ^^^^^^^^^^^^^^^^^^^^^^^^^^^^^
  File "/Library/Frameworks/Python.framework/Versions/3.12/lib/python3.12/site-packages/urllib3/util/connection.py", line 95, in create_connection
    raise err
  File "/Library/Frameworks/Python.framework/Versions/3.12/lib/python3.12/site-packages/urllib3/util/connection.py", line 85, in create_connection
    sock.connect(sa)
TimeoutError: timed out

During handling of the above exception, another exception occurred:

Traceback (most recent call last):
  File "/Library/Frameworks/Python.framework/Versions/3.12/lib/python3.12/site-packages/urllib3/connectionpool.py", line 716, in urlopen
    httplib_response = self._make_request(
                       ^^^^^^^^^^^^^^^^^^^
  File "/Library/Frameworks/Python.framework/Versions/3.12/lib/python3.12/site-packages/urllib3/connectionpool.py", line 404, in _make_request
    self._validate_conn(conn)
  File "/Library/Frameworks/Python.framework/Versions/3.12/lib/python3.12/site-packages/urllib3/connectionpool.py", line 1061, in _validate_conn
    conn.connect()
  File "/Library/Frameworks/Python.framework/Versions/3.12/lib/python3.12/site-packages/urllib3/connection.py", line 363, in connect
    self.sock = conn = self._new_conn()
                       ^^^^^^^^^^^^^^^^
  File "/Library/Frameworks/Python.framework/Versions/3.12/lib/python3.12/site-packages/urllib3/connection.py", line 179, in _new_conn
    raise ConnectTimeoutError(
urllib3.exceptions.ConnectTimeoutError: (<urllib3.connection.HTTPSConnection object at 0x107d999d0>, 'Connection to api.wandb.ai timed out. (connect timeout=20)')

During handling of the above exception, another exception occurred:

Traceback (most recent call last):
  File "/Library/Frameworks/Python.framework/Versions/3.12/lib/python3.12/site-packages/requests/adapters.py", line 489, in send
    resp = conn.urlopen(
           ^^^^^^^^^^^^^
  File "/Library/Frameworks/Python.framework/Versions/3.12/lib/python3.12/site-packages/urllib3/connectionpool.py", line 802, in urlopen
    retries = retries.increment(
              ^^^^^^^^^^^^^^^^^^
  File "/Library/Frameworks/Python.framework/Versions/3.12/lib/python3.12/site-packages/urllib3/util/retry.py", line 594, in increment
    raise MaxRetryError(_pool, url, error or ResponseError(cause))
urllib3.exceptions.MaxRetryError: HTTPSConnectionPool(host='api.wandb.ai', port=443): Max retries exceeded with url: /graphql (Caused by ConnectTimeoutError(<urllib3.connection.HTTPSConnection object at 0x107d999d0>, 'Connection to api.wandb.ai timed out. (connect timeout=20)'))

During handling of the above exception, another exception occurred:

Traceback (most recent call last):
  File "/Library/Frameworks/Python.framework/Versions/3.12/lib/python3.12/site-packages/wandb/sdk/lib/retry.py", line 131, in __call__
    result = self._call_fn(*args, **kwargs)
             ^^^^^^^^^^^^^^^^^^^^^^^^^^^^^^
  File "/Library/Frameworks/Python.framework/Versions/3.12/lib/python3.12/site-packages/wandb/sdk/internal/internal_api.py", line 347, in execute
    return self.client.execute(*args, **kwargs)  # type: ignore
           ^^^^^^^^^^^^^^^^^^^^^^^^^^^^^^^^^^^^
  File "/Library/Frameworks/Python.framework/Versions/3.12/lib/python3.12/site-packages/wandb/vendor/gql-0.2.0/wandb_gql/client.py", line 52, in execute
    result = self._get_result(document, *args, **kwargs)
             ^^^^^^^^^^^^^^^^^^^^^^^^^^^^^^^^^^^^^^^^^^^
  File "/Library/Frameworks/Python.framework/Versions/3.12/lib/python3.12/site-packages/wandb/vendor/gql-0.2.0/wandb_gql/client.py", line 60, in _get_result
    return self.transport.execute(document, *args, **kwargs)
           ^^^^^^^^^^^^^^^^^^^^^^^^^^^^^^^^^^^^^^^^^^^^^^^^^
  File "/Library/Frameworks/Python.framework/Versions/3.12/lib/python3.12/site-packages/wandb/sdk/lib/gql_request.py", line 58, in execute
    request = self.session.post(self.url, **post_args)
              ^^^^^^^^^^^^^^^^^^^^^^^^^^^^^^^^^^^^^^^^
  File "/Library/Frameworks/Python.framework/Versions/3.12/lib/python3.12/site-packages/requests/sessions.py", line 635, in post
    return self.request("POST", url, data=data, json=json, **kwargs)
           ^^^^^^^^^^^^^^^^^^^^^^^^^^^^^^^^^^^^^^^^^^^^^^^^^^^^^^^^^
  File "/Library/Frameworks/Python.framework/Versions/3.12/lib/python3.12/site-packages/requests/sessions.py", line 587, in request
    resp = self.send(prep, **send_kwargs)
           ^^^^^^^^^^^^^^^^^^^^^^^^^^^^^^
  File "/Library/Frameworks/Python.framework/Versions/3.12/lib/python3.12/site-packages/requests/sessions.py", line 701, in send
    r = adapter.send(request, **kwargs)
        ^^^^^^^^^^^^^^^^^^^^^^^^^^^^^^^
  File "/Library/Frameworks/Python.framework/Versions/3.12/lib/python3.12/site-packages/requests/adapters.py", line 553, in send
    raise ConnectTimeout(e, request=request)
requests.exceptions.ConnectTimeout: HTTPSConnectionPool(host='api.wandb.ai', port=443): Max retries exceeded with url: /graphql (Caused by ConnectTimeoutError(<urllib3.connection.HTTPSConnection object at 0x107d999d0>, 'Connection to api.wandb.ai timed out. (connect timeout=20)'))
2024-10-08 12:56:23,591 ERROR   MainThread:86111 [wandb_init.py:init():838] encountered error: Run initialization has timed out after 90.0 sec. 
Please refer to the documentation for additional information: https://docs.wandb.ai/guides/track/tracking-faq#initstarterror-error-communicating-with-wandb-process-
2024-10-08 12:56:23,592 ERROR   MainThread:86111 [wandb_init.py:init():1262] error in wandb.init()
Traceback (most recent call last):
  File "/Library/Frameworks/Python.framework/Versions/3.12/lib/python3.12/site-packages/wandb/sdk/wandb_init.py", line 1252, in init
    return wi.init()
           ^^^^^^^^^
  File "/Library/Frameworks/Python.framework/Versions/3.12/lib/python3.12/site-packages/wandb/sdk/wandb_init.py", line 844, in init
    raise error
wandb.errors.errors.CommError: Run initialization has timed out after 90.0 sec. 
Please refer to the documentation for additional information: https://docs.wandb.ai/guides/track/tracking-faq#initstarterror-error-communicating-with-wandb-process-
2024-10-08 12:56:23,759 WARNING MsgRouterThr:86111 [router.py:message_loop():77] message_loop has been closed
